<?xml version="1.0" encoding="utf-8"?>
<robot name="my_car" xmlns:xacro="http://www.ros.org/wiki/xacro">
  <link name="base_laser">
    <inertial>
      <origin rpy="0 0 0" xyz="-0.00029774 0.0066667 0.00013047"/>
      <mass value="0.15717"/>
      <inertia ixx="6.7885E-05" ixy="-1.3987E-07" ixz="-8.1554E-07" iyy="0.00013173" iyz="-9.0932E-08" izz="7.1972E-05"/>
    </inertial>
    <visual>
      <origin rpy="0 0 0" xyz="0 0 0"/>
      <geometry>
        <mesh filename="package://my_car/meshes/ydlidar.dae"/>
      </geometry>
      <material name="">
        <color rgba="0.64706 0.61961 0.58824 1"/>
      </material>
    </visual>
    <collision>
      <origin rpy="0 0 0" xyz="0 0 0"/>
      <geometry>
        <mesh filename="package://my_car/meshes/ydlidar.dae"/>
      </geometry>
    </collision>
  </link>
  <link name="laser_frame">
    <inertial>
      <origin rpy="0 0 0" xyz="-0.00036659 0.00064155 -0.00027052"/>
      <mass value="0.25482"/>
      <inertia ixx="8.9194E-05" ixy="1.8116E-07" ixz="3.6435E-08" iyy="0.00018279" iyz="2.423E-07" izz="0.00011103"/>
    </inertial>
  </link>

  <joint name="laser_joint" type="fixed">
    <origin rpy="0 0 0" xyz="0 0 0.03172"/>
    <parent link="base_laser"/>
    <child link="laser_frame"/>
  </joint>
  
  <link name= "my_car_ch">
    </link>
  <joint name="my_car_ch_joint" type="fixed">
    <origin rpy="0 0 0" xyz="0 0 0"/>
    <parent link="my_car_ch"/>
    <child link="base_link"/>
    <axis xyz="0 0 0" rpy="0 0 0"/>
  </joint>
  <link name="base_link">
    <inertial>
      <origin rpy="0 0 0" xyz="0.065609 0.17971 -6.3539E-18"/>
      <mass value="90.437"/>
      <inertia ixx="2.3213" ixy="-0.11083" ixz="-1.8146E-08" iyy="6.741" iyz="-5.9043E-17" izz="5.5108"/>
    </inertial>
    <visual>
      <origin rpy="0 0 0" xyz="0 0 0"/>
      <geometry>
        <mesh filename="package://my_car/meshes/base_link.STL"/>
      </geometry>
      <material name="">
        <color rgba="0.79216 0.81961 0.93333 1"/>
      </material>
    </visual>
    <!-- <collision>
      <origin rpy="0 0 0" xyz="0 0 0"/>
      <geometry>
        <mesh filename="package://my_car/meshes/base_link.STL"/>
      </geometry>
    </collision> -->
  </link>

  <link name="front_left_steering">
    <inertial>
      <origin rpy="0 0 0" xyz="0 0 0"/>
      <mass value="2.4413"/>
      <inertia ixx="0.0075579" ixy="-1.5134E-18" ixz="-5.4803E-34" iyy="0.012751" iyz="-3.0127E-19" izz="0.0075579"/>
    </inertial>
  </link>
  <joint name="front_left_steering_joint" type="revolute">
    <origin rpy="0 0 3.1416" xyz="-0.26353 -0.2159 0.11466"/>
    <parent link="base_link"/>
    <child link="front_left_steering"/>
    <axis xyz="0 0 1"/>
    <limit effort="500" lower="-0.785" upper="0.785" velocity="100"/>
  </joint>
  <link name="front_left_wheel">
    <inertial>
      <origin rpy="0 0 0" xyz="0 0 0"/>
      <mass value="2.4413"/>
      <inertia ixx="0.0075579" ixy="-1.5134E-18" ixz="-5.4803E-34" iyy="0.012751" iyz="-3.0127E-19" izz="0.0075579"/>
    </inertial>
    <visual>
      <origin rpy="0 0 0" xyz="0 0 0"/>
      <geometry>
        <mesh filename="package://my_car/meshes/front_right_steering.STL"/>
      </geometry>
      <material name="">
        <color rgba="0.79216 0.81961 0.93333 1"/>
      </material>
    </visual>
    <collision>
      <origin rpy="1.57 0 0" xyz="0 0 0"/>
      <geometry>
        <cylinder radius="0.1" length="0.075"/>
      </geometry>
    </collision>
  </link>
  <joint name="front_left_wheel_joint" type="continuous">
    <origin rpy="0 0 3.1416" xyz="0 0 0"/>
    <parent link="front_left_steering"/>
    <child link="front_left_wheel"/>
    <axis xyz="0 -1 0"/>
  </joint>
  <!-- <link name="front_left_steering">
    <inertial>
      <origin rpy="0 0 0" xyz="0 0 0"/>
      <mass value="2.4413"/>
      <inertia ixx="0.0075579" ixy="-9.2586E-21" ixz="-1.8188E-35" iyy="0.012751" iyz="5.7305E-35" izz="0.0075579"/>
    </inertial>
  </link>
  <joint name="front_left_steering_joint" type="revolute">
    <origin rpy="0 0 3.1416" xyz="-0.26353 -0.2159 0.11466"/>
    <parent link="base_link"/>
    <child link="front_left_steering"/>
    <axis xyz="0 0 1"/>
    <limit effort="500" lower="-0.785" upper="0.785" velocity="100"/>
  </joint>
  <link name="front_left_wheel">
    <inertial>
      <origin rpy="0 0 0" xyz="0 0 0"/>
      <mass value="2.4413"/>
      <inertia ixx="0.0075579" ixy="-9.2586E-21" ixz="-1.8188E-35" iyy="0.012751" iyz="5.7305E-35" izz="0.0075579"/>
    </inertial>
    <visual>
      <origin rpy="0 0 0" xyz="0 0 0"/>
      <geometry>
        <mesh filename="package://my_car/meshes/front_left_steering.STL"/>
      </geometry>
      <material name="">
        <color rgba="0.79216 0.81961 0.93333 1"/>
      </material>
    </visual>
    <collision>
      <origin rpy="1.57 0 0" xyz="0 0 0"/>
      <geometry>
        <cylinder radius="0.1" length="0.075"/>
      </geometry>
    </collision>
  </link>
  <joint name="front_left_wheel_joint" type="continuous">
    <origin rpy="0 0 3.1416" xyz="0 0 0"/>
    <parent link="front_left_steering"/>
    <child link="front_left_wheel"/>
    <axis xyz="0 1 0"/>
  </joint> -->
  <link name="front_right_steering">
    <inertial>
      <origin rpy="0 0 0" xyz="0 0 0"/>
      <mass value="2.4413"/>
      <inertia ixx="0.0075579" ixy="-1.5134E-18" ixz="-5.4803E-34" iyy="0.012751" iyz="-3.0127E-19" izz="0.0075579"/>
    </inertial>
  </link>
  <joint name="front_right_steering_joint" type="revolute">
    <origin rpy="0 0 3.1416" xyz="-0.26353 0.2159 0.11466"/>
    <parent link="base_link"/>
    <child link="front_right_steering"/>
    <axis xyz="0 0 1"/>
    <limit effort="500" lower="-0.785" upper="0.785" velocity="100"/>
  </joint>
  <link name="front_right_wheel">
    <inertial>
      <origin rpy="0 0 0" xyz="0 0 0"/>
      <mass value="2.4413"/>
      <inertia ixx="0.0075579" ixy="-1.5134E-18" ixz="-5.4803E-34" iyy="0.012751" iyz="-3.0127E-19" izz="0.0075579"/>
    </inertial>
    <visual>
      <origin rpy="0 0 0" xyz="0 0 0"/>
      <geometry>
        <mesh filename="package://my_car/meshes/front_right_steering.STL"/>
      </geometry>
      <material name="">
        <color rgba="0.79216 0.81961 0.93333 1"/>
      </material>
    </visual>
    <collision>
      <origin rpy="1.57 0 0" xyz="0 0 0"/>
      <geometry>
        <cylinder radius="0.1" length="0.075"/>
      </geometry>
    </collision>
  </link>
  <joint name="front_right_wheel_joint" type="continuous">
    <origin rpy="0 0 3.1416" xyz="0 0 0"/>
    <parent link="front_right_steering"/>
    <child link="front_right_wheel"/>
    <axis xyz="0 -1 0"/>
  </joint>
  <link name="rear_wheels">
    <inertial>
      <origin rpy="0 0 0" xyz="0 0 0"/>
      <mass value="4.8826"/>
      <inertia ixx="0.015116" ixy="1.2777E-20" ixz="-9.7389E-19" iyy="0.025501" iyz="3.5405E-19" izz="0.015116"/>
    </inertial>
    <visual>
      <origin rpy="0 0 0" xyz="0 0 0"/>
      <geometry>
        <mesh filename="package://my_car/meshes/rear_wheels.STL"/>
      </geometry>
      <material name="">
        <color rgba="0.79216 0.81961 0.93333 1"/>
      </material>
    </visual>
    <collision>
      <origin rpy="1.57 0 0" xyz="0 0.2 0"/>
      <geometry>
        <cylinder radius="0.1" length="0.075"/>
      </geometry>
    </collision>
    <collision>
      <origin rpy="1.57 0 0" xyz="0 -0.2 0"/>
      <geometry>
        <cylinder radius="0.1" length="0.075"/>
      </geometry>
    </collision>
  </link>
  <joint name="rear_wheels_joint" type="continuous">
    <origin rpy="0 0 0" xyz="0.254 0 0.075"/>
    <parent link="base_link"/>
    <child link="rear_wheels"/>
    <axis xyz="0 -1 0"/>
    <limit effort="5000" velocity="100"/>
  </joint>
  <transmission name="front_left_trans">
    <type>transmission_interface/SimpleTransmission</type>
    <joint name="front_left_steering_joint">
      <hardwareInterface>hardware_interface/EffortJointInterface</hardwareInterface>
    </joint>
    <actuator name="motor1">
      <hardwareInterface>hardware_interface/EffortJointInterface</hardwareInterface>
      <mechanicalReduction>1</mechanicalReduction>
    </actuator>
  </transmission>
  <transmission name="front_right_trans">
    <type>transmission_interface/SimpleTransmission</type>
    <joint name="front_right_steering_joint">
      <hardwareInterface>hardware_interface/EffortJointInterface</hardwareInterface>
    </joint>
    <actuator name="motor2">
      <hardwareInterface>hardware_interface/EffortJointInterface</hardwareInterface>
      <mechanicalReduction>1</mechanicalReduction>
    </actuator>
  </transmission>
  <transmission name="rear_trans">
    <type>transmission_interface/SimpleTransmission</type>
    <joint name="rear_wheels_joint">
      <hardwareInterface>hardware_interface/EffortJointInterface</hardwareInterface>
    </joint>
    <actuator name="motor3">
      <hardwareInterface>hardware_interface/EffortJointInterface</hardwareInterface>
      <mechanicalReduction>1</mechanicalReduction>
    </actuator>
  </transmission>
  <joint name="lidar_joint" type="fixed">
    <origin rpy="0 -0.08 3.14" xyz="0 0 0.355"/>
    <parent link="base_link"/>
    <child link="base_laser"/>
  </joint>
  <gazebo>
    <plugin filename="libgazebo_ros_control.so" name="gazebo_ros_control">
      <robotNamespace>/</robotNamespace>
    </plugin>
  </gazebo>
  <gazebo reference="laser_frame">
    <sensor type="ray" name="head_hokuyo_sensor">
      <pose>0 0 0 0 0 0</pose>
      <visualize>true</visualize>
      <update_rate>40</update_rate>
      <ray>
        <scan>
          <horizontal>
            <samples>720</samples>
            <resolution>1</resolution>
            <min_angle>-1.570796</min_angle>
            <max_angle>1.570796</max_angle>
          </horizontal>
        </scan>
        <range>
          <min>0.10</min>
          <max>30.0</max>
          <resolution>0.01</resolution>
        </range>
        <noise>
          <type>gaussian</type>
          <!-- Noise parameters based on published spec for Hokuyo laser
               achieving "+-30mm" accuracy at range < 10m.  A mean of 0.0m and
               stddev of 0.01m will put 99.7% of samples within 0.03m of the true
               reading. -->
          <mean>0.0</mean>
          <stddev>0.01</stddev>
        </noise>
      </ray>
      <plugin name="gazebo_ros_head_hokuyo_controller" filename="libgazebo_ros_laser.so">
        <topicName>/laser/scan</topicName>
        <frameName>laser_frame</frameName>
      </plugin>
    </sensor>
  </gazebo>
</robot>
